Workbook

Sheet MEMO
A1: REIMBURSEMENT REQUEST FOR AN EXTERNAL BENEFICIARY | G1: Finance Department | K1: =IF(liste!A1="","",liste!A1) -> Entity | L1: =IF(liste!B1="","",liste!B1) -> Devises | M1: =IF(liste!C1="","",liste!C1) -> Activité | N1: =IF(liste!D1="","",liste!D1) -> Nom Pays | O1: =IF(liste!E1="","",liste!E1) -> ISO | P1: =IF(liste!F1="","",liste!F1) | Q1: =IF(liste!G1="","",liste!G1) -> libellé anglais | R1: =IF(liste!H1="","",liste!H1) -> libellé français | ... AH1: =IF(liste!X1="","",liste!X1) | AI1: =IF(liste!Z1="","",liste!Z1) | AJ1: =IF(liste!AA1="","",liste!AA1) | AK1: =IF(liste!AB1="","",liste!AB1) | AL1: =IF(liste!AC1="","",liste!AC1) | AM1: =IF(liste!AD1="","",liste!AD1) | AN1: =IF(liste!AE1="","",liste!AE1) | AO1: =IF(liste!AF1="","",liste!AF1) | AP1: =IF(liste!AG1="","",liste!AG1) | ... AW1: =IF(liste!AN1="","",liste!AN1)
K2: =IF(liste!A2="","",liste!A2) -> FONDATION INSEAD | L2: =IF(liste!B2="","",liste!B2) -> AED | M2: =IF(liste!C2="","",liste!C2) -> Other | N2: =IF(liste!D2="","",liste!D2) -> FRANCE | O2: =IF(liste!E2="","",liste!E2) -> FR | P2: =IF(liste!F2="","",liste!F2) | Q2: =IF(liste!G2="","",liste!G2) -> CNF conferences | R2: =IF(liste!H2="","",liste!H2) | ... AG2: =IF(liste!W2="","",liste!W2) | AH2: ="ATTESTATION, I the above named "&F5&" certify that in the context of a Research Seminar the “Beneficiary” (Speaker) addressed a group of interested faculty and students. The speaker has received no fee for this service, but INSEAD is reimbursing his travel and local expenses." -> ATTESTATION, I the above named Claire DURAND certify that in the context of a Research Seminar the “Beneficiary” (Speaker) addressed a group of interested faculty and students. The speaker has received no fee for this service, but INSEAD is reimbursing his travel and local expenses.
A3: Important : 1) Please complete every section in this document and return by internal mail to Accounts Payable Department together with all supporting receipts. 2) Please tape receipts to an A4 sheet of paper. | K3: =IF(liste!A3="","",liste!A3) -> INSEAD EUROPE | L3: =IF(liste!B3="","",liste!B3) -> EUR | M3: =IF(liste!C3="","",liste!C3) -> Alumni | N3: =IF(liste!D3="","",liste!D3) -> UNITED ARAB EMIRATES | O3: =IF(liste!E3="","",liste!E3) -> AE | P3: =IF(liste!F3="","",liste!F3) | Q3: =IF(liste!G3="","",liste!G3) -> Courier & postage | R3: =IF(liste!H3="","",liste!H3) | ... AH3: =IF(liste!X3="","",liste!X3)
K4: =IF(liste!A4="","",liste!A4) -> INSEAD ABU DHABI | L4: =IF(liste!B4="","",liste!B4) -> GBP | M4: =IF(liste!C4="","",liste!C4) -> Board Member | N4: =IF(liste!D4="","",liste!D4) -> SINGAPORE | O4: =IF(liste!E4="","",liste!E4) -> SG | P4: =IF(liste!F4="","",liste!F4) | Q4: =IF(liste!G4="","",liste!G4) -> DOC books, magazines, newspapers | R4: =IF(liste!H4="","",liste!H4) | ... AH4: =IF(liste!X4="","",liste!X4)
A5: Document Number | B5: CD021025A | D5: Requested By | F5: Claire DURAND | K5: =IF(liste!A5="","",liste!A5) -> INSEAD RESIDENCES | L5: =IF(liste!B5="","",liste!B5) -> USD | M5: =IF(liste!C5="","",liste!C5) -> Coach | N5: =IF(liste!D5="","",liste!D5) -> AFGHANISTAN | O5: =IF(liste!E5="","",liste!E5) -> AF | P5: =IF(liste!F5="","",liste!F5) | Q5: =IF(liste!G5="","",liste!G5) -> Equipment rental | R5: =IF(liste!H5="","",liste!H5) | ... AH5: =IF(liste!X5="","",liste!X5)
A6: Document Date | B6: 45932 | D6: Tel Ext | F6: 9042 | K6: =IF(liste!A6="","",liste!A6) -> INSEAD SINGAPORE | L6: =IF(liste!B6="","",liste!B6) -> SGD | M6: =IF(liste!C6="","",liste!C6) -> Co-Author | N6: =IF(liste!D6="","",liste!D6) -> ÅLAND ISLANDS | O6: =IF(liste!E6="","",liste!E6) -> AX | P6: =IF(liste!F6="","",liste!F6) | Q6: =IF(liste!G6="","",liste!G6) -> HOT hotel & accommodation | R6: =IF(liste!H6="","",liste!H6) | ... AF6: =IF(liste!V6="","",liste!V6) -> 28
K7: =IF(liste!A7="","",liste!A7) | L7: =IF(liste!B7="","",liste!B7) | M7: =IF(liste!C7="","",liste!C7) -> Coordinator | N7: =IF(liste!D7="","",liste!D7) -> ALBANIA | O7: =IF(liste!E7="","",liste!E7) -> AL | P7: =IF(liste!F7="","",liste!F7) | Q7: =IF(liste!G7="","",liste!G7) -> Library books | R7: =IF(liste!H7="","",liste!H7) | ... AF7: =IF(liste!V7="","",liste!V7) -> 18
A8: Entity | B8: INSEAD EUROPE | K8: =IF(liste!A8="","",liste!A8) | L8: =IF(liste!B8="","",liste!B8) | M8: =IF(liste!C8="","",liste!C8) -> Emba Student | N8: =IF(liste!D8="","",liste!D8) -> ALGERIA | O8: =IF(liste!E8="","",liste!E8) -> DZ | P8: =IF(liste!F8="","",liste!F8) | Q8: =IF(liste!G8="","",liste!G8) -> OTHER | R8: =IF(liste!H8="","",liste!H8) | ... AF8: =IF(liste!V8="","",liste!V8) -> 24
K9: =IF(liste!A9="","",liste!A9) | L9: =IF(liste!B9="","",liste!B9) | M9: =IF(liste!C9="","",liste!C9) -> Emeritus Faculty | N9: =IF(liste!D9="","",liste!D9) -> AMERICAN SAMOA | O9: =IF(liste!E9="","",liste!E9) -> AS | P9: =IF(liste!F9="","",liste!F9) | Q9: =IF(liste!G9="","",liste!G9) -> Other miscellaneous taxes | R9: =IF(liste!H9="","",liste!H9) | ... AF9: =IF(liste!V9="","",liste!V9) -> 20
A10: GENERAL INFORMATION OF BENEFICIARY | K10: =IF(liste!A10="","",liste!A10) | L10: =IF(liste!B10="","",liste!B10) | M10: =IF(liste!C10="","",liste!C10) -> Guest EDP | N10: =IF(liste!D10="","",liste!D10) -> ANDORRA | O10: =IF(liste!E10="","",liste!E10) -> AD | P10: =IF(liste!F10="","",liste!F10) | Q10: =IF(liste!G10="","",liste!G10) -> Pedagogical material | R10: =IF(liste!H10="","",liste!H10) | ... AF10: =IF(liste!V10="","",liste!V10) -> 18
K11: =IF(liste!A11="","",liste!A11) | L11: =IF(liste!B11="","",liste!B11) | M11: =IF(liste!C11="","",liste!C11) -> Guest Speaker | N11: =IF(liste!D11="","",liste!D11) -> ANGOLA | O11: =IF(liste!E11="","",liste!E11) -> AO | P11: =IF(liste!F11="","",liste!F11) | Q11: =IF(liste!G11="","",liste!G11) -> PKG parking, toll | R11: =IF(liste!H11="","",liste!H11) | ... AF11: =IF(liste!V11="","",liste!V11) -> 27
A12: Last Name of Beneficiary | B12: KUMAR | K12: =IF(liste!A12="","",liste!A12) | L12: =IF(liste!B12="","",liste!B12) | M12: =IF(liste!C12="","",liste!C12) -> IT Technician | N12: =IF(liste!D12="","",liste!D12) -> ANGUILLA | O12: =IF(liste!E12="","",liste!E12) -> AI | P12: =IF(liste!F12="","",liste!F12) | Q12: =IF(liste!G12="","",liste!G12) -> PLA plane | R12: =IF(liste!H12="","",liste!H12) | ... AF12: =IF(liste!V12="","",liste!V12) -> 27
A13: First Name of Beneficiary | B13: Vineet | K13: =IF(liste!A13="","",liste!A13) | L13: =IF(liste!B13="","",liste!B13) | M13: =IF(liste!C13="","",liste!C13) -> Mba Student | N13: =IF(liste!D13="","",liste!D13) -> ANTARCTICA | O13: =IF(liste!E13="","",liste!E13) -> AQ | P13: =IF(liste!F13="","",liste!F13) | Q13: =IF(liste!G13="","",liste!G13) -> Presents, gifts | R13: =IF(liste!H13="","",liste!H13) | ... AF13: =IF(liste!V13="","",liste!V13) -> 28
K14: =IF(liste!A14="","",liste!A14) | L14: =IF(liste!B14="","",liste!B14) | M14: =IF(liste!C14="","",liste!C14) -> Participant | N14: =IF(liste!D14="","",liste!D14) -> ANTIGUA AND BARBUDA | O14: =IF(liste!E14="","",liste!E14) -> AG | P14: =IF(liste!F14="","",liste!F14) | Q14: =IF(liste!G14="","",liste!G14) -> RES meals, restaurant | R14: =IF(liste!H14="","",liste!H14) | ... AF14: =IF(liste!V14="","",liste!V14) -> 22
A15: Type of activity | B15: Recruitment Candidate | D15: Email | E15: kumar.vineet@gmail.com | K15: =IF(liste!A15="","",liste!A15) | L15: =IF(liste!B15="","",liste!B15) | M15: =IF(liste!C15="","",liste!C15) -> Phd Student | N15: =IF(liste!D15="","",liste!D15) -> ARGENTINA | O15: =IF(liste!E15="","",liste!E15) -> AR | P15: =IF(liste!F15="","",liste!F15) | Q15: =IF(liste!G15="","",liste!G15) -> TAX taxi | R15: =IF(liste!H15="","",liste!H15) | ... AF15: =IF(liste!V15="","",liste!V15) -> 26
K16: =IF(liste!A16="","",liste!A16) | L16: =IF(liste!B16="","",liste!B16) | M16: =IF(liste!C16="","",liste!C16) -> Recruitment Candidate | N16: =IF(liste!D16="","",liste!D16) -> ARMENIA | O16: =IF(liste!E16="","",liste!E16) -> AM | P16: =IF(liste!F16="","",liste!F16) | Q16: =IF(liste!G16="","",liste!G16) -> Technical supplies | R16: =IF(liste!H16="","",liste!H16) | ... AF16: =IF(liste!V16="","",liste!V16) -> 27
A17: Address of Beneficiary | D17: Postal Code | G17: =IF(E19="","",VLOOKUP(E19,N2:O251,2,FALSE())) | K17: =IF(liste!A17="","",liste!A17) | L17: =IF(liste!B17="","",liste!B17) | M17: =IF(liste!C17="","",liste!C17) -> Research Assistant | N17: =IF(liste!D17="","",liste!D17) -> ARUBA | O17: =IF(liste!E17="","",liste!E17) -> AW | P17: =IF(liste!F17="","",liste!F17) | Q17: =IF(liste!G17="","",liste!G17) -> TEL telecom & internet | R17: =IF(liste!H17="","",liste!H17) | ... AF17: =IF(liste!V17="","",liste!V17) -> 21
D18: City | K18: =IF(liste!A18="","",liste!A18) | L18: =IF(liste!B18="","",liste!B18) | M18: =IF(liste!C18="","",liste!C18) -> Temporary Staff | N18: =IF(liste!D18="","",liste!D18) -> AUSTRALIA | O18: =IF(liste!E18="","",liste!E18) -> AU | P18: =IF(liste!F18="","",liste!F18) | Q18: =IF(liste!G18="","",liste!G18) -> TRA train | R18: =IF(liste!H18="","",liste!H18) | ... AF18: =IF(liste!V18="","",liste!V18) -> 21
D19: Country | K19: =IF(liste!A19="","",liste!A19) | L19: =IF(liste!B19="","",liste!B19) | M19: =IF(liste!C19="","",liste!C19) -> Visiting Professor | N19: =IF(liste!D19="","",liste!D19) -> AUSTRIA | O19: =IF(liste!E19="","",liste!E19) -> AT | P19: =IF(liste!F19="","",liste!F19) | Q19: =IF(liste!G19="","",liste!G19) -> Visa | R19: =IF(liste!H19="","",liste!H19) | ... AF19: =IF(liste!V19="","",liste!V19) -> 20
K20: =IF(liste!A20="","",liste!A20) | L20: =IF(liste!B20="","",liste!B20) | M20: =IF(liste!C20="","",liste!C20) | N20: =IF(liste!D20="","",liste!D20) -> AZERBAIJAN | O20: =IF(liste!E20="","",liste!E20) -> AZ | P20: =IF(liste!F20="","",liste!F20) | Q20: =IF(liste!G20="","",liste!G20) | R20: =IF(liste!H20="","",liste!H20) | ... AF20: =IF(liste!V20="","",liste!V20) -> 20
A21: EXPENSE DETAILS | K21: =IF(liste!A21="","",liste!A21) | L21: =IF(liste!B21="","",liste!B21) | M21: =IF(liste!C21="","",liste!C21) | N21: =IF(liste!D21="","",liste!D21) -> BAHAMAS | O21: =IF(liste!E21="","",liste!E21) -> BS | P21: =IF(liste!F21="","",liste!F21) | Q21: =IF(liste!G21="","",liste!G21) | R21: =IF(liste!H21="","",liste!H21) | ... AF21: =IF(liste!V21="","",liste!V21) -> 31
K22: =IF(liste!A22="","",liste!A22) | L22: =IF(liste!B22="","",liste!B22) | M22: =IF(liste!C22="","",liste!C22) | N22: =IF(liste!D22="","",liste!D22) -> BAHRAIN | O22: =IF(liste!E22="","",liste!E22) -> BH | P22: =IF(liste!F22="","",liste!F22) | Q22: =IF(liste!G22="","",liste!G22) | R22: =IF(liste!H22="","",liste!H22) | ... AF22: =IF(liste!V22="","",liste!V22) -> 15
A23: Duration | B23: From | C23: 30 September 2025 | D23: To | E23: 02 October 2025 | K23: =IF(liste!A23="","",liste!A23) | L23: =IF(liste!B23="","",liste!B23) | M23: =IF(liste!C23="","",liste!C23) | N23: =IF(liste!D23="","",liste!D23) -> BANGLADESH | O23: =IF(liste!E23="","",liste!E23) -> BD | P23: =IF(liste!F23="","",liste!F23) | Q23: =IF(liste!G23="","",liste!G23) | R23: =IF(liste!H23="","",liste!H23) | ... AF23: =IF(liste!V23="","",liste!V23) -> 18
K24: =IF(liste!A24="","",liste!A24) | L24: =IF(liste!B24="","",liste!B24) | M24: =IF(liste!C24="","",liste!C24) | N24: =IF(liste!D24="","",liste!D24) -> BARBADOS | O24: =IF(liste!E24="","",liste!E24) -> BB | P24: =IF(liste!F24="","",liste!F24) | Q24: =IF(liste!G24="","",liste!G24) | R24: =IF(liste!H24="","",liste!H24) | ... AF24: =IF(liste!V24="","",liste!V24) -> 28
A25: Main Destination | B25: City | C25: Fontainebleau | D25: Country | E25: FRANCE | K25: =IF(liste!A25="","",liste!A25) | L25: =IF(liste!B25="","",liste!B25) | M25: =IF(liste!C25="","",liste!C25) | N25: =IF(liste!D25="","",liste!D25) -> BELARUS | O25: =IF(liste!E25="","",liste!E25) -> BY | P25: =IF(liste!F25="","",liste!F25) | Q25: =IF(liste!G25="","",liste!G25) | R25: =IF(liste!H25="","",liste!H25) | ... AF25: =IF(liste!V25="","",liste!V25) -> 25
K26: =IF(liste!A26="","",liste!A26) | L26: =IF(liste!B26="","",liste!B26) | M26: =IF(liste!C26="","",liste!C26) | N26: =IF(liste!D26="","",liste!D26) -> BELGIUM | O26: =IF(liste!E26="","",liste!E26) -> BE | P26: =IF(liste!F26="","",liste!F26) | Q26: =IF(liste!G26="","",liste!G26) | R26: =IF(liste!H26="","",liste!H26) | ... AF26: =IF(liste!V26="","",liste!V26) -> 24
A27: Reason for expense | B27: MKT Area - Recruitment visit - Vineet Kumar | K27: =IF(liste!A27="","",liste!A27) | L27: =IF(liste!B27="","",liste!B27) | M27: =IF(liste!C27="","",liste!C27) | N27: =IF(liste!D27="","",liste!D27) -> BELIZE | O27: =IF(liste!E27="","",liste!E27) -> BZ | P27: =IF(liste!F27="","",liste!F27) | Q27: =IF(liste!G27="","",liste!G27) | R27: =IF(liste!H27="","",liste!H27) | ... AF27: =IF(liste!V27="","",liste!V27) -> 24
K28: =IF(liste!A28="","",liste!A28) | L28: =IF(liste!B28="","",liste!B28) | M28: =IF(liste!C28="","",liste!C28) | N28: =IF(liste!D28="","",liste!D28) -> BENIN | O28: =IF(liste!E28="","",liste!E28) -> BJ | P28: =IF(liste!F28="","",liste!F28) | Q28: =IF(liste!G28="","",liste!G28) | R28: =IF(liste!H28="","",liste!H28) | ... AF28: =IF(liste!V28="","",liste!V28) -> 22
K29: =IF(liste!A29="","",liste!A29) | L29: =IF(liste!B29="","",liste!B29) | M29: =IF(liste!C29="","",liste!C29) | N29: =IF(liste!D29="","",liste!D29) -> BERMUDA | O29: =IF(liste!E29="","",liste!E29) -> BM | P29: =IF(liste!F29="","",liste!F29) | Q29: =IF(liste!G29="","",liste!G29) | R29: =IF(liste!H29="","",liste!H29) | ... AF29: =IF(liste!V29="","",liste!V29) -> 24
A30: Budget Code | B30: 1120 | C30: Sub-Budget Code | D30: 001 MKT | K30: =IF(liste!A30="","",liste!A30) | L30: =IF(liste!B30="","",liste!B30) | M30: =IF(liste!C30="","",liste!C30) | N30: =IF(liste!D30="","",liste!D30) -> BHUTAN | O30: =IF(liste!E30="","",liste!E30) -> BT | P30: =IF(liste!F30="","",liste!F30) | Q30: =IF(liste!G30="","",liste!G30) | R30: =IF(liste!H30="","",liste!H30) | ... AF30: =IF(liste!V30="","",liste!V30) -> 19
K31: =IF(liste!A31="","",liste!A31) | L31: =IF(liste!B31="","",liste!B31) | M31: =IF(liste!C31="","",liste!C31) | N31: =IF(liste!D31="","",liste!D31) -> BOLIVIA | O31: =IF(liste!E31="","",liste!E31) -> BO | P31: =IF(liste!F31="","",liste!F31) | Q31: =IF(liste!G31="","",liste!G31) | R31: =IF(liste!H31="","",liste!H31) | ... AF31: =IF(liste!V31="","",liste!V31) -> 24
A32: Choose payment currency | B32: USD | C32: Note : Currencies accepted for payment   AED - EUR - GBP - USD - SGD | K32: =IF(liste!A32="","",liste!A32) | L32: =IF(liste!B32="","",liste!B32) | M32: =IF(liste!C32="","",liste!C32) | N32: =IF(liste!D32="","",liste!D32) -> BONAIRE | O32: =IF(liste!E32="","",liste!E32) -> BQ | P32: =IF(liste!F32="","",liste!F32) | Q32: =IF(liste!G32="","",liste!G32) | R32: =IF(liste!H32="","",liste!H32) | ... AF32: =IF(liste!V32="","",liste!V32)
K33: =IF(liste!A33="","",liste!A33) | L33: =IF(liste!B33="","",liste!B33) | M33: =IF(liste!C33="","",liste!C33) | N33: =IF(liste!D33="","",liste!D33) -> BOSNIA AND HERZEGOVINA | O33: =IF(liste!E33="","",liste!E33) -> BA | P33: =IF(liste!F33="","",liste!F33) | Q33: =IF(liste!G33="","",liste!G33) | R33: =IF(liste!H33="","",liste!H33) | ... AF33: =IF(liste!V33="","",liste!V33)
A34: List of Expenses | B34: Code | C34: Description | D34: Amount | E34: Currency | F34: Currency rate | G34: Total | K34: =IF(liste!A34="","",liste!A34) | L34: =IF(liste!B34="","",liste!B34) | M34: =IF(liste!C34="","",liste!C34) | N34: =IF(liste!D34="","",liste!D34) -> BOTSWANA | O34: =IF(liste!E34="","",liste!E34) -> BW | P34: =IF(liste!F34="","",liste!F34) | Q34: =IF(liste!G34="","",liste!G34) | R34: =IF(liste!H34="","",liste!H34) | ... AF34: =IF(liste!V34="","",liste!V34)
K35: =IF(liste!A35="","",liste!A35) | L35: =IF(liste!B35="","",liste!B35) | M35: =IF(liste!C35="","",liste!C35) | N35: =IF(liste!D35="","",liste!D35) -> BOUVET ISLAND | O35: =IF(liste!E35="","",liste!E35) -> BV | P35: =IF(liste!F35="","",liste!F35) | Q35: =IF(liste!G35="","",liste!G35) | R35: =IF(liste!H35="","",liste!H35) | ... AF35: =IF(liste!V35="","",liste!V35)
A36: PLA plane | C36: Outgoing Flight | D36: 1803.88 | E36: USD United States Dollar | F36: 1 | G36: 1803.88 | K36: =IF(liste!A36="","",liste!A36) | L36: =IF(liste!B36="","",liste!B36) | M36: =IF(liste!C36="","",liste!C36) | N36: =IF(liste!D36="","",liste!D36) -> BRAZIL | O36: =IF(liste!E36="","",liste!E36) -> BR | P36: =IF(liste!F36="","",liste!F36) | Q36: =IF(liste!G36="","",liste!G36) | R36: =IF(liste!H36="","",liste!H36) | ... AF36: =IF(liste!V36="","",liste!V36)
A37: Visa | C37: Visa Fee for entry into France | D37: 104 | E37: USD United States Dollar | G37: 104 | K37: =IF(liste!A37="","",liste!A37) | L37: =IF(liste!B37="","",liste!B37) | M37: =IF(liste!C37="","",liste!C37) | N37: =IF(liste!D37="","",liste!D37) -> BRITISH INDIAN OCEAN TERRITORY | O37: =IF(liste!E37="","",liste!E37) -> IO | P37: =IF(liste!F37="","",liste!F37) | Q37: =IF(liste!G37="","",liste!G37) | R37: =IF(liste!H37="","",liste!H37) | ... AF37: =IF(liste!V37="","",liste!V37)
A38: TAX taxi | C38: Boston Airport to Home | D38: 33.98 | E38: USD United States Dollar | G38: 33.98 | K38: =IF(liste!A38="","",liste!A38) | L38: =IF(liste!B38="","",liste!B38) | M38: =IF(liste!C38="","",liste!C38) | N38: =IF(liste!D38="","",liste!D38) -> BRUNEI DARUSSALAM | O38: =IF(liste!E38="","",liste!E38) -> BN | P38: =IF(liste!F38="","",liste!F38) | Q38: =IF(liste!G38="","",liste!G38) | R38: =IF(liste!H38="","",liste!H38) | ... AF38: =IF(liste!V38="","",liste!V38)
K39: =IF(liste!A39="","",liste!A39) | L39: =IF(liste!B39="","",liste!B39) | M39: =IF(liste!C39="","",liste!C39) | N39: =IF(liste!D39="","",liste!D39) -> BULGARIA | O39: =IF(liste!E39="","",liste!E39) -> BG | P39: =IF(liste!F39="","",liste!F39) | Q39: =IF(liste!G39="","",liste!G39) | R39: =IF(liste!H39="","",liste!H39) | ... AF39: =IF(liste!V39="","",liste!V39)
K40: =IF(liste!A40="","",liste!A40) | L40: =IF(liste!B40="","",liste!B40) | M40: =IF(liste!C40="","",liste!C40) | N40: =IF(liste!D40="","",liste!D40) -> BURKINA FASO | O40: =IF(liste!E40="","",liste!E40) -> BF | P40: =IF(liste!F40="","",liste!F40) | Q40: =IF(liste!G40="","",liste!G40) | R40: =IF(liste!H40="","",liste!H40) | ... AF40: =IF(liste!V40="","",liste!V40)
...

Sheet liste
A1: Entity | B1: Devises | C1: Activité | D1: Nom Pays | E1: ISO | G1: libellé anglais | H1: libellé français | I1: Code nature | K1: code nature global (rouge => enlevé) | O1: devise | T1: IBAN
A2: FONDATION INSEAD | B2: AED | C2: Other | D2: FRANCE | E2: FR | G2: CNF conferences | I2: F100 | K2: B001 | L2: translators | M2: traducteurs | O2: United Arab Emirates Dirham | P2: AED | Q2: =P2&" "&O2 -> AED United Arab Emirates Dirham | T2: DE | U2: Allemagne | V2: 22 | X2: ATTESTATION I the above named (“Requested by” cell) certify that in the context of a Research Seminar the “Beneficiary” (Speaker) addressed a group of interested faculty and students. The speaker has received no fee for this service, but INSEAD is reimbursing his travel and local expenses.
A3: INSEAD EUROPE | B3: EUR | C3: Alumni | D3: UNITED ARAB EMIRATES | E3: AE | G3: Courier & postage | I3: G402 | K3: B002 | L3: speakers | M3: conférenciers | O3: Euro Member Countries Eur | P3: EUR | Q3: =P3&" "&O3 -> EUR Euro Member Countries Eur | T3: AT | U3: Autriche | V3: 20
A4: INSEAD ABU DHABI | B4: GBP | C4: Board Member | D4: SINGAPORE | E4: SG | G4: DOC books, magazines, newspapers | I4: C403 | K4: B003 | L4: graders & tutorial assistance | M4: graders & tutorial assistance | O4: Great Britain Pound | P4: GBP | Q4: =P4&" "&O4 -> GBP Great Britain Pound | T4: BE | U4: Belgique | V4: 16
A5: INSEAD RESIDENCES | B5: USD | C5: Coach | D5: AFGHANISTAN | E5: AF | G5: Equipment rental | I5: E200 | K5: B005 | L5: relocation agency fees | M5: honoraires installation personnel | O5: United States Dollar | P5: USD | Q5: =P5&" "&O5 -> USD United States Dollar | T5: BG | U5: Bulgarie | V5: 22
A6: INSEAD SINGAPORE | B6: SGD | C6: Co-Author | D6: ÅLAND ISLANDS | E6: AX | G6: HOT hotel & accommodation | I6: F402/F502 | K6: B006 | L6: recruitment agency fees | M6: honoraires recrutement | O6: Singapore Dollar | P6: SGD | Q6: =P6&" "&O6 -> SGD Singapore Dollar | T6: CY | U6: Chypre | V6: 28
C7: Coordinator | D7: ALBANIA | E7: AL | G7: Library books | I7: C301 | K7: B007 | L7: coaching fees | M7: honoraires des coachs | O7: Albania Lek | P7: ALL | Q7: =P7&" "&O7 -> ALL Albania Lek | T7: DK | U7: Danemark | V7: 18
C8: Emba Student | D8: ALGERIA | E8: DZ | G8: OTHER | I8: 0 | K8: B008 | L8: fees for simulations | M8: honoraires de simulation | O8: Algeria Dinar | P8: DZD | Q8: =P8&" "&O8 -> DZD Algeria Dinar | T8: ES | U8: Espagne | V8: 24
C9: Emeritus Faculty | D9: AMERICAN SAMOA | E9: AS | G9: Other miscellaneous taxes | I9: J309 | K9: B010 | L9: other pgm services | M9: honoraires autres intervenants pgms | O9: Angola Kwanza | P9: AOA | Q9: =P9&" "&O9 -> AOA Angola Kwanza | T9: EE | U9: Estonie | V9: 20
C10: Guest EDP | D10: ANDORRA | E10: AD | G10: Pedagogical material | I10: C303 | K10: B101 | L10: overload fees permanent faculty | M10: honoraires profs permanents (enseignement) | O10: Argentina Peso | P10: ARS | Q10: =P10&" "&O10 -> ARS Argentina Peso | T10: FI | U10: Finlande | V10: 18
C11: Guest Speaker | D11: ANGOLA | E11: AO | G11: PKG parking, toll | I11: F403/F502 | K11: B103 | L11: teaching fees visiting faculty | M11: honoraires profs visitants (enseignement) | O11: Armenia Dram | P11: AMD | Q11: =P11&" "&O11 -> AMD Armenia Dram | T11: FR | U11: France | V11: 27
C12: IT Technician | D12: ANGUILLA | E12: AI | G12: PLA plane | I12: F401/F501 | K12: B110 | L12: preparation fees | M12: honoraires de préparation | O12: Aruba Guilder | P12: AWG | Q12: =P12&" "&O12 -> AWG Aruba Guilder | T12: GR | U12: Grèce | V12: 27
C13: Mba Student | D13: ANTARCTICA | E13: AQ | G13: Presents, gifts | I13: F002 | K13: B112 | L13: research-related professional fees | M13: honoraires de recherche | O13: Australia Dollar | P13: AUD | Q13: =P13&" "&O13 -> AUD Australia Dollar | T13: HU | U13: Hongrie | V13: 28
C14: Participant | D14: ANTIGUA AND BARBUDA | E14: AG | G14: RES meals, restaurant | I14: F402/F502 | K14: B113 | L14: fees for developing teaching material | M14: honoraires développement matériel pédagogique | O14: Azerbaijan Manat | P14: AZN | Q14: =P14&" "&O14 -> AZN Azerbaijan Manat | T14: IE | U14: Irlande | V14: 22
C15: Phd Student | D15: ARGENTINA | E15: AR | G15: TAX taxi | I15: F402/F501 | K15: B170 | L15: fees for marketing & public relations | M15: honoraires de marketing et relations publiques | O15: Bahamas Dollar | P15: BSD | Q15: =P15&" "&O15 -> BSD Bahamas Dollar | T15: IS | U15: Islande | V15: 26
C16: Recruitment Candidate | D16: ARMENIA | E16: AM | G16: Technical supplies | I16: C101 | K16: B180 | L16: professional advisory fees | M16: honoraires conseils et experts | O16: Bahrain Dinar | P16: BHD | Q16: =P16&" "&O16 -> BHD Bahrain Dinar | T16: IT | U16: Italie | V16: 27
C17: Research Assistant | D17: ARUBA | E17: AW | G17: TEL telecom & internet | I17: F403/F502 | K17: B190 | L17: consulting fees | M17: honoraires de conseil | O17: Bangladesh Taka | P17: BDT | Q17: =P17&" "&O17 -> BDT Bangladesh Taka | T17: LV | U17: Lettonie | V17: 21
C18: Temporary Staff | D18: AUSTRALIA | E18: AU | G18: TRA train | I18: F402/F501 | O18: Barbados Dollar | P18: BBD | Q18: =P18&" "&O18 -> BBD Barbados Dollar | T18: LI | U18: Liechtenstein | V18: 21
C19: Visiting Professor | D19: AUSTRIA | E19: AT | G19: Visa | I19: J301 | K19: B210 | L19: staff from another campus | M19: personnel détaché | O19: Belize Dollar | P19: BZD | Q19: =P19&" "&O19 -> BZD Belize Dollar | T19: LT | U19: Lituanie | V19: 20
D20: AZERBAIJAN | E20: AZ | K20: A530 | L20: school fees | M20: frais de scolarité des enfants | O20: Bermuda Dollar | P20: BMD | Q20: =P20&" "&O20 -> BMD Bermuda Dollar | T20: LU | U20: Luxembourg | V20: 20
D21: BAHAMAS | E21: BS | K21: B300 | L21: trainees indemnities | M21: indemnités de stage | O21: Bhutan Ngultrum | P21: BTN | Q21: =P21&" "&O21 -> BTN Bhutan Ngultrum | T21: MT | U21: Malte | V21: 31
D22: BAHRAIN | E22: BH | K22: C001 | L22: water (utility) | M22: eau | O22: Bolivia Boliviano | P22: BOB | Q22: =P22&" "&O22 -> BOB Bolivia Boliviano | T22: NO | U22: Norvège | V22: 15
D23: BANGLADESH | E23: BD | K23: C002 | L23: electricity (utility) | M23: électricité | O23: Botswana Pula | P23: BWP | Q23: =P23&" "&O23 -> BWP Botswana Pula | T23: NL | U23: Pays-Bas | V23: 18
D24: BARBADOS | E24: BB | K24: C003 | L24: gas (utility) | M24: gaz | O24: Brazil Real | P24: BRL | Q24: =P24&" "&O24 -> BRL Brazil Real | T24: PL | U24: Pologne | V24: 28
D25: BELARUS | E25: BY | K25: C004 | L25: other énergy | M25: autres énergies | O25: Brunei Dollar | P25: BND | Q25: =P25&" "&O25 -> BND Brunei Dollar | T25: PT | U25: Portugal | V25: 25
D26: BELGIUM | E26: BE | K26: C101 | L26: technical supplies | M26: fournitures techniques | O26: Bulgaria Leva | P26: BGN | Q26: =P26&" "&O26 -> BGN Bulgaria Leva | T26: CZ | U26: République Tchèque | V26: 24
D27: BELIZE | E27: BZ | K27: C102 | L27: tools and small equipment | M27: petit outillage et matériel | O27: Burundi Franc | P27: BIF | Q27: =P27&" "&O27 -> BIF Burundi Franc | T27: RO | U27: Roumanie | V27: 24
D28: BENIN | E28: BJ | K28: C103 | L28: maintenance products | M28: produits entretien | O28: Cambodia Riel | P28: KHR | Q28: =P28&" "&O28 -> KHR Cambodia Riel | T28: GB | U28: Royaume-Uni | V28: 22
D29: BERMUDA | E29: BM | K29: C104 | L29: welcome products | M29: produits d'accueil | O29: Canada Dollar | P29: CAD | Q29: =P29&" "&O29 -> CAD Canada Dollar | T29: SK | U29: Slovaquie | V29: 24
D30: BHUTAN | E30: BT | K30: C105 | L30: tableware | M30: vaisselle-verrerie | O30: Cape Verde Escudo | P30: CVE | Q30: =P30&" "&O30 -> CVE Cape Verde Escudo | T30: SI | U30: Slovénie | V30: 19
D31: BOLIVIA | E31: BO | K31: C107 | L31: ICT small equipment IT | M31: ICT petit mat IT | O31: Chile Peso | P31: CLP | Q31: =P31&" "&O31 -> CLP Chile Peso | T31: SE | U31: Suède | V31: 24
D32: BONAIRE | E32: BQ | K32: C201 | L32: stationery & office supplies | M32: papeterie et fournitures de bureau | O32: China Yuan | P32: CNY | Q32: =P32&" "&O32 -> CNY China Yuan
D33: BOSNIA AND HERZEGOVINA | E33: BA | K33: C202 | L33: bulk papers & envelopes | M33: papier et enveloppes | O33: China Yuan (business or offshore only) | P33: CNH | Q33: =P33&" "&O33 -> CNH China Yuan (business or offshore only)
D34: BOTSWANA | E34: BW | K34: C203 | L34: computer supplies | M34: fournitures informatiques | O34: Colombia Peso | P34: COP | Q34: =P34&" "&O34 -> COP Colombia Peso
D35: BOUVET ISLAND | E35: BV | K35: C205 | L35: software | M35: logiciel | O35: Commuanute Financiere BCEAO Africaine Franc | P35: XOF | Q35: =P35&" "&O35 -> XOF Commuanute Financiere BCEAO Africaine Franc
D36: BRAZIL | E36: BR | K36: C301 | L36: library books | M36: livres bibliothèque | O36: Commuanute Financiere BEAC Africaine Franc | P36: XAF | Q36: =P36&" "&O36 -> XAF Commuanute Financiere BEAC Africaine Franc
D37: BRITISH INDIAN OCEAN TERRITORY | E37: IO | K37: C302 | L37: subscription library | M37: abonnements bibliothèque | O37: Comoros Franc | P37: KMF | Q37: =P37&" "&O37 -> KMF Comoros Franc
D38: BRUNEI DARUSSALAM | E38: BN | K38: C303 | L38: pedagogical material | M38: matériel pédagogique | O38: Costa Rica Colon | P38: CRC | Q38: =P38&" "&O38 -> CRC Costa Rica Colon
D39: BULGARIA | E39: BG | K39: C305 | L39: data base | M39: achat base de données | O39: Croatia Kuna | P39: HRK | Q39: =P39&" "&O39 -> HRK Croatia Kuna
D40: BURKINA FASO | E40: BF | K40: C306 | L40: decoration & flowers | M40: décoration et fleurs | O40: Cyprus Pound | P40: CYP | Q40: =P40&" "&O40 -> CYP Cyprus Pound
...

Sheet phd
A1: VOIR TITRE - SCHOLARSHIP PHD - TEMPORARY STAFF | G1: Finance Department | K1: =IF(liste!A1="","",liste!A1) -> Entity | L1: =IF(liste!B1="","",liste!B1) -> Devises | M1: =IF(liste!C1="","",liste!C1) -> Activité | N1: =IF(liste!D1="","",liste!D1) -> Nom Pays | O1: =IF(liste!E1="","",liste!E1) -> ISO | P1: =IF(liste!F1="","",liste!F1) | Q1: =IF(liste!G1="","",liste!G1) -> libellé anglais | R1: =IF(liste!H1="","",liste!H1) -> libellé français | ... AF1: =IF(liste!V1="","",liste!V1) | AG1: =IF(liste!X1="","",liste!X1) | AH1: =IF(liste!Y1="","",liste!Y1) | AI1: =IF(liste!#ref!="","",liste!#ref!) -> #NAME? | AJ1: =IF(liste!X1="","",liste!X1) | AK1: =IF(liste!Y1="","",liste!Y1) | AL1: =IF(liste!Z1="","",liste!Z1) | AM1: =IF(liste!AA1="","",liste!AA1) | AN1: =IF(liste!AB1="","",liste!AB1) | AO1: =IF(liste!AC1="","",liste!AC1) | AP1: =IF(liste!AD1="","",liste!AD1) | AQ1: =IF(liste!AE1="","",liste!AE1) | ... AZ1: =IF(liste!AN1="","",liste!AN1)
K2: =IF(liste!A2="","",liste!A2) -> FONDATION INSEAD | L2: =IF(liste!B2="","",liste!B2) -> AED | M2: =IF(liste!C2="","",liste!C2) -> Other | N2: =IF(liste!D2="","",liste!D2) -> FRANCE | O2: =IF(liste!E2="","",liste!E2) -> FR | P2: =IF(liste!F2="","",liste!F2) | Q2: =IF(liste!G2="","",liste!G2) -> CNF conferences | R2: =IF(liste!H2="","",liste!H2) | ... AF2: =IF(liste!V2="","",liste!V2) -> 22
A3: Important : 1) Please complete every section in this document. 2) Return form and supporting documents by internal mail or by email to accounts.payable@insead.edu. | K3: =IF(liste!A3="","",liste!A3) -> INSEAD EUROPE | L3: =IF(liste!B3="","",liste!B3) -> EUR | M3: =IF(liste!C3="","",liste!C3) -> Alumni | N3: =IF(liste!D3="","",liste!D3) -> UNITED ARAB EMIRATES | O3: =IF(liste!E3="","",liste!E3) -> AE | P3: =IF(liste!F3="","",liste!F3) | Q3: =IF(liste!G3="","",liste!G3) -> Courier & postage | R3: =IF(liste!H3="","",liste!H3) | ... AF3: =IF(liste!V3="","",liste!V3) -> 20
K4: =IF(liste!A4="","",liste!A4) -> INSEAD ABU DHABI | L4: =IF(liste!B4="","",liste!B4) -> GBP | M4: =IF(liste!C4="","",liste!C4) -> Board Member | N4: =IF(liste!D4="","",liste!D4) -> SINGAPORE | O4: =IF(liste!E4="","",liste!E4) -> SG | P4: =IF(liste!F4="","",liste!F4) | Q4: =IF(liste!G4="","",liste!G4) -> DOC books, magazines, newspapers | R4: =IF(liste!H4="","",liste!H4) | ... AF4: =IF(liste!V4="","",liste!V4) -> 16
A5: Document Number | D5: Requested By | K5: =IF(liste!A5="","",liste!A5) -> INSEAD RESIDENCES | L5: =IF(liste!B5="","",liste!B5) -> USD | M5: =IF(liste!C5="","",liste!C5) -> Coach | N5: =IF(liste!D5="","",liste!D5) -> AFGHANISTAN | O5: =IF(liste!E5="","",liste!E5) -> AF | P5: =IF(liste!F5="","",liste!F5) | Q5: =IF(liste!G5="","",liste!G5) -> Equipment rental | R5: =IF(liste!H5="","",liste!H5) | ... AF5: =IF(liste!V5="","",liste!V5) -> 22
A6: Document Date | D6: Tel Ext | K6: =IF(liste!A6="","",liste!A6) -> INSEAD SINGAPORE | L6: =IF(liste!B6="","",liste!B6) -> SGD | M6: =IF(liste!C6="","",liste!C6) -> Co-Author | N6: =IF(liste!D6="","",liste!D6) -> ÅLAND ISLANDS | O6: =IF(liste!E6="","",liste!E6) -> AX | P6: =IF(liste!F6="","",liste!F6) | Q6: =IF(liste!G6="","",liste!G6) -> HOT hotel & accommodation | R6: =IF(liste!H6="","",liste!H6) | ... AF6: =IF(liste!V6="","",liste!V6) -> 28
K7: =IF(liste!A7="","",liste!A7) | L7: =IF(liste!B7="","",liste!B7) | M7: =IF(liste!C7="","",liste!C7) -> Coordinator | N7: =IF(liste!D7="","",liste!D7) -> ALBANIA | O7: =IF(liste!E7="","",liste!E7) -> AL | P7: =IF(liste!F7="","",liste!F7) | Q7: =IF(liste!G7="","",liste!G7) -> Library books | R7: =IF(liste!H7="","",liste!H7) | ... AF7: =IF(liste!V7="","",liste!V7) -> 18
A8: Entity | K8: =IF(liste!A8="","",liste!A8) | L8: =IF(liste!B8="","",liste!B8) | M8: =IF(liste!C8="","",liste!C8) -> Emba Student | N8: =IF(liste!D8="","",liste!D8) -> ALGERIA | O8: =IF(liste!E8="","",liste!E8) -> DZ | P8: =IF(liste!F8="","",liste!F8) | Q8: =IF(liste!G8="","",liste!G8) -> OTHER | R8: =IF(liste!H8="","",liste!H8) | ... AF8: =IF(liste!V8="","",liste!V8) -> 24
K9: =IF(liste!A9="","",liste!A9) | L9: =IF(liste!B9="","",liste!B9) | M9: =IF(liste!C9="","",liste!C9) -> Emeritus Faculty | N9: =IF(liste!D9="","",liste!D9) -> AMERICAN SAMOA | O9: =IF(liste!E9="","",liste!E9) -> AS | P9: =IF(liste!F9="","",liste!F9) | Q9: =IF(liste!G9="","",liste!G9) -> Other miscellaneous taxes | R9: =IF(liste!H9="","",liste!H9) | ... AF9: =IF(liste!V9="","",liste!V9) -> 20
A10: GENERAL INFORMATION OF BENEFICIARY | K10: =IF(liste!A10="","",liste!A10) | L10: =IF(liste!B10="","",liste!B10) | M10: =IF(liste!C10="","",liste!C10) -> Guest EDP | N10: =IF(liste!D10="","",liste!D10) -> ANDORRA | O10: =IF(liste!E10="","",liste!E10) -> AD | P10: =IF(liste!F10="","",liste!F10) | Q10: =IF(liste!G10="","",liste!G10) -> Pedagogical material | R10: =IF(liste!H10="","",liste!H10) | ... AF10: =IF(liste!V10="","",liste!V10) -> 18
K11: =IF(liste!A11="","",liste!A11) | L11: =IF(liste!B11="","",liste!B11) | M11: =IF(liste!C11="","",liste!C11) -> Guest Speaker | N11: =IF(liste!D11="","",liste!D11) -> ANGOLA | O11: =IF(liste!E11="","",liste!E11) -> AO | P11: =IF(liste!F11="","",liste!F11) | Q11: =IF(liste!G11="","",liste!G11) -> PKG parking, toll | R11: =IF(liste!H11="","",liste!H11) | ... AF11: =IF(liste!V11="","",liste!V11) -> 27
A12: Last Name of Beneficiary | K12: =IF(liste!A12="","",liste!A12) | L12: =IF(liste!B12="","",liste!B12) | M12: =IF(liste!C12="","",liste!C12) -> IT Technician | N12: =IF(liste!D12="","",liste!D12) -> ANGUILLA | O12: =IF(liste!E12="","",liste!E12) -> AI | P12: =IF(liste!F12="","",liste!F12) | Q12: =IF(liste!G12="","",liste!G12) -> PLA plane | R12: =IF(liste!H12="","",liste!H12) | ... AF12: =IF(liste!V12="","",liste!V12) -> 27
A13: First Name of Beneficiary | K13: =IF(liste!A13="","",liste!A13) | L13: =IF(liste!B13="","",liste!B13) | M13: =IF(liste!C13="","",liste!C13) -> Mba Student | N13: =IF(liste!D13="","",liste!D13) -> ANTARCTICA | O13: =IF(liste!E13="","",liste!E13) -> AQ | P13: =IF(liste!F13="","",liste!F13) | Q13: =IF(liste!G13="","",liste!G13) -> Presents, gifts | R13: =IF(liste!H13="","",liste!H13) | ... AF13: =IF(liste!V13="","",liste!V13) -> 28
K14: =IF(liste!A14="","",liste!A14) | L14: =IF(liste!B14="","",liste!B14) | M14: =IF(liste!C14="","",liste!C14) -> Participant | N14: =IF(liste!D14="","",liste!D14) -> ANTIGUA AND BARBUDA | O14: =IF(liste!E14="","",liste!E14) -> AG | P14: =IF(liste!F14="","",liste!F14) | Q14: =IF(liste!G14="","",liste!G14) -> RES meals, restaurant | R14: =IF(liste!H14="","",liste!H14) | ... AF14: =IF(liste!V14="","",liste!V14) -> 22
A15: Type of activity | D15: Email | K15: =IF(liste!A15="","",liste!A15) | L15: =IF(liste!B15="","",liste!B15) | M15: =IF(liste!C15="","",liste!C15) -> Phd Student | N15: =IF(liste!D15="","",liste!D15) -> ARGENTINA | O15: =IF(liste!E15="","",liste!E15) -> AR | P15: =IF(liste!F15="","",liste!F15) | Q15: =IF(liste!G15="","",liste!G15) -> TAX taxi | R15: =IF(liste!H15="","",liste!H15) | ... AF15: =IF(liste!V15="","",liste!V15) -> 26
K16: =IF(liste!A16="","",liste!A16) | L16: =IF(liste!B16="","",liste!B16) | M16: =IF(liste!C16="","",liste!C16) -> Recruitment Candidate | N16: =IF(liste!D16="","",liste!D16) -> ARMENIA | O16: =IF(liste!E16="","",liste!E16) -> AM | P16: =IF(liste!F16="","",liste!F16) | Q16: =IF(liste!G16="","",liste!G16) -> Technical supplies | R16: =IF(liste!H16="","",liste!H16) | ... AF16: =IF(liste!V16="","",liste!V16) -> 27
A17: Address of Beneficiary | D17: Postal Code | G17: =IF(E19="","",VLOOKUP(E19,N2:O251,2,FALSE())) | K17: =IF(liste!A17="","",liste!A17) | L17: =IF(liste!B17="","",liste!B17) | M17: =IF(liste!C17="","",liste!C17) -> Research Assistant | N17: =IF(liste!D17="","",liste!D17) -> ARUBA | O17: =IF(liste!E17="","",liste!E17) -> AW | P17: =IF(liste!F17="","",liste!F17) | Q17: =IF(liste!G17="","",liste!G17) -> TEL telecom & internet | R17: =IF(liste!H17="","",liste!H17) | ... AF17: =IF(liste!V17="","",liste!V17) -> 21
D18: City | K18: =IF(liste!A18="","",liste!A18) | L18: =IF(liste!B18="","",liste!B18) | M18: =IF(liste!C18="","",liste!C18) -> Temporary Staff | N18: =IF(liste!D18="","",liste!D18) -> AUSTRALIA | O18: =IF(liste!E18="","",liste!E18) -> AU | P18: =IF(liste!F18="","",liste!F18) | Q18: =IF(liste!G18="","",liste!G18) -> TRA train | R18: =IF(liste!H18="","",liste!H18) | ... AF18: =IF(liste!V18="","",liste!V18) -> 21
D19: Country | K19: =IF(liste!A19="","",liste!A19) | L19: =IF(liste!B19="","",liste!B19) | M19: =IF(liste!C19="","",liste!C19) -> Visiting Professor | N19: =IF(liste!D19="","",liste!D19) -> AUSTRIA | O19: =IF(liste!E19="","",liste!E19) -> AT | P19: =IF(liste!F19="","",liste!F19) | Q19: =IF(liste!G19="","",liste!G19) -> Visa | R19: =IF(liste!H19="","",liste!H19) | ... AF19: =IF(liste!V19="","",liste!V19) -> 20
K20: =IF(liste!A20="","",liste!A20) | L20: =IF(liste!B20="","",liste!B20) | M20: =IF(liste!C20="","",liste!C20) | N20: =IF(liste!D20="","",liste!D20) -> AZERBAIJAN | O20: =IF(liste!E20="","",liste!E20) -> AZ | P20: =IF(liste!F20="","",liste!F20) | Q20: =IF(liste!G20="","",liste!G20) | R20: =IF(liste!H20="","",liste!H20) | ... AF20: =IF(liste!V20="","",liste!V20) -> 20
A21: EXPENSE DETAILS | K21: =IF(liste!A21="","",liste!A21) | L21: =IF(liste!B21="","",liste!B21) | M21: =IF(liste!C21="","",liste!C21) | N21: =IF(liste!D21="","",liste!D21) -> BAHAMAS | O21: =IF(liste!E21="","",liste!E21) -> BS | P21: =IF(liste!F21="","",liste!F21) | Q21: =IF(liste!G21="","",liste!G21) | R21: =IF(liste!H21="","",liste!H21) | ... AF21: =IF(liste!V21="","",liste!V21) -> 31
K22: =IF(liste!A22="","",liste!A22) | L22: =IF(liste!B22="","",liste!B22) | M22: =IF(liste!C22="","",liste!C22) | N22: =IF(liste!D22="","",liste!D22) -> BAHRAIN | O22: =IF(liste!E22="","",liste!E22) -> BH | P22: =IF(liste!F22="","",liste!F22) | Q22: =IF(liste!G22="","",liste!G22) | R22: =IF(liste!H22="","",liste!H22) | ... AF22: =IF(liste!V22="","",liste!V22) -> 15
A23: Duration | B23: From | D23: To | K23: =IF(liste!A23="","",liste!A23) | L23: =IF(liste!B23="","",liste!B23) | M23: =IF(liste!C23="","",liste!C23) | N23: =IF(liste!D23="","",liste!D23) -> BANGLADESH | O23: =IF(liste!E23="","",liste!E23) -> BD | P23: =IF(liste!F23="","",liste!F23) | Q23: =IF(liste!G23="","",liste!G23) | R23: =IF(liste!H23="","",liste!H23) | ... AF23: =IF(liste!V23="","",liste!V23) -> 18
K24: =IF(liste!A24="","",liste!A24) | L24: =IF(liste!B24="","",liste!B24) | M24: =IF(liste!C24="","",liste!C24) | N24: =IF(liste!D24="","",liste!D24) -> BARBADOS | O24: =IF(liste!E24="","",liste!E24) -> BB | P24: =IF(liste!F24="","",liste!F24) | Q24: =IF(liste!G24="","",liste!G24) | R24: =IF(liste!H24="","",liste!H24) | ... AF24: =IF(liste!V24="","",liste!V24) -> 28
A25: Main Destination | B25: City | D25: Country | K25: =IF(liste!A25="","",liste!A25) | L25: =IF(liste!B25="","",liste!B25) | M25: =IF(liste!C25="","",liste!C25) | N25: =IF(liste!D25="","",liste!D25) -> BELARUS | O25: =IF(liste!E25="","",liste!E25) -> BY | P25: =IF(liste!F25="","",liste!F25) | Q25: =IF(liste!G25="","",liste!G25) | R25: =IF(liste!H25="","",liste!H25) | ... AF25: =IF(liste!V25="","",liste!V25) -> 25
K26: =IF(liste!A26="","",liste!A26) | L26: =IF(liste!B26="","",liste!B26) | M26: =IF(liste!C26="","",liste!C26) | N26: =IF(liste!D26="","",liste!D26) -> BELGIUM | O26: =IF(liste!E26="","",liste!E26) -> BE | P26: =IF(liste!F26="","",liste!F26) | Q26: =IF(liste!G26="","",liste!G26) | R26: =IF(liste!H26="","",liste!H26) | ... AF26: =IF(liste!V26="","",liste!V26) -> 24
A27: Reason for expense | K27: =IF(liste!A27="","",liste!A27) | L27: =IF(liste!B27="","",liste!B27) | M27: =IF(liste!C27="","",liste!C27) | N27: =IF(liste!D27="","",liste!D27) -> BELIZE | O27: =IF(liste!E27="","",liste!E27) -> BZ | P27: =IF(liste!F27="","",liste!F27) | Q27: =IF(liste!G27="","",liste!G27) | R27: =IF(liste!H27="","",liste!H27) | ... AF27: =IF(liste!V27="","",liste!V27) -> 24
K28: =IF(liste!A28="","",liste!A28) | L28: =IF(liste!B28="","",liste!B28) | M28: =IF(liste!C28="","",liste!C28) | N28: =IF(liste!D28="","",liste!D28) -> BENIN | O28: =IF(liste!E28="","",liste!E28) -> BJ | P28: =IF(liste!F28="","",liste!F28) | Q28: =IF(liste!G28="","",liste!G28) | R28: =IF(liste!H28="","",liste!H28) | ... AF28: =IF(liste!V28="","",liste!V28) -> 22
K29: =IF(liste!A29="","",liste!A29) | L29: =IF(liste!B29="","",liste!B29) | M29: =IF(liste!C29="","",liste!C29) | N29: =IF(liste!D29="","",liste!D29) -> BERMUDA | O29: =IF(liste!E29="","",liste!E29) -> BM | P29: =IF(liste!F29="","",liste!F29) | Q29: =IF(liste!G29="","",liste!G29) | R29: =IF(liste!H29="","",liste!H29) | ... AF29: =IF(liste!V29="","",liste!V29) -> 24
A30: Budget Code | C30: Sub-Budget Code | K30: =IF(liste!A30="","",liste!A30) | L30: =IF(liste!B30="","",liste!B30) | M30: =IF(liste!C30="","",liste!C30) | N30: =IF(liste!D30="","",liste!D30) -> BHUTAN | O30: =IF(liste!E30="","",liste!E30) -> BT | P30: =IF(liste!F30="","",liste!F30) | Q30: =IF(liste!G30="","",liste!G30) | R30: =IF(liste!H30="","",liste!H30) | ... AF30: =IF(liste!V30="","",liste!V30) -> 19
K31: =IF(liste!A31="","",liste!A31) | L31: =IF(liste!B31="","",liste!B31) | M31: =IF(liste!C31="","",liste!C31) | N31: =IF(liste!D31="","",liste!D31) -> BOLIVIA | O31: =IF(liste!E31="","",liste!E31) -> BO | P31: =IF(liste!F31="","",liste!F31) | Q31: =IF(liste!G31="","",liste!G31) | R31: =IF(liste!H31="","",liste!H31) | ... AF31: =IF(liste!V31="","",liste!V31) -> 24
A32: Choose payment currency | C32: Note : Currencies accepted for payment   AED - EUR - GBP - USD - SGD | K32: =IF(liste!A32="","",liste!A32) | L32: =IF(liste!B32="","",liste!B32) | M32: =IF(liste!C32="","",liste!C32) | N32: =IF(liste!D32="","",liste!D32) -> BONAIRE | O32: =IF(liste!E32="","",liste!E32) -> BQ | P32: =IF(liste!F32="","",liste!F32) | Q32: =IF(liste!G32="","",liste!G32) | R32: =IF(liste!H32="","",liste!H32) | ... AF32: =IF(liste!V32="","",liste!V32)
K33: =IF(liste!A33="","",liste!A33) | L33: =IF(liste!B33="","",liste!B33) | M33: =IF(liste!C33="","",liste!C33) | N33: =IF(liste!D33="","",liste!D33) -> BOSNIA AND HERZEGOVINA | O33: =IF(liste!E33="","",liste!E33) -> BA | P33: =IF(liste!F33="","",liste!F33) | Q33: =IF(liste!G33="","",liste!G33) | R33: =IF(liste!H33="","",liste!H33) | ... AF33: =IF(liste!V33="","",liste!V33)
A34: List of Expenses | B34: Code | C34: Description | D34: Payment | K34: =IF(liste!A34="","",liste!A34) | L34: =IF(liste!B34="","",liste!B34) | M34: =IF(liste!C34="","",liste!C34) | N34: =IF(liste!D34="","",liste!D34) -> BOTSWANA | O34: =IF(liste!E34="","",liste!E34) -> BW | P34: =IF(liste!F34="","",liste!F34) | Q34: =IF(liste!G34="","",liste!G34) | R34: =IF(liste!H34="","",liste!H34) | ... AF34: =IF(liste!V34="","",liste!V34)
D35: By | E35: Type | G35: Amount | K35: =IF(liste!A35="","",liste!A35) | L35: =IF(liste!B35="","",liste!B35) | M35: =IF(liste!C35="","",liste!C35) | N35: =IF(liste!D35="","",liste!D35) -> BOUVET ISLAND | O35: =IF(liste!E35="","",liste!E35) -> BV | P35: =IF(liste!F35="","",liste!F35) | Q35: =IF(liste!G35="","",liste!G35) | R35: =IF(liste!H35="","",liste!H35) | ... AF35: =IF(liste!V35="","",liste!V35)
K36: =IF(liste!A36="","",liste!A36) | L36: =IF(liste!B36="","",liste!B36) | M36: =IF(liste!C36="","",liste!C36) | N36: =IF(liste!D36="","",liste!D36) -> BRAZIL | O36: =IF(liste!E36="","",liste!E36) -> BR | P36: =IF(liste!F36="","",liste!F36) | Q36: =IF(liste!G36="","",liste!G36) | R36: =IF(liste!H36="","",liste!H36) | ... AF36: =IF(liste!V36="","",liste!V36)
K37: =IF(liste!A37="","",liste!A37) | L37: =IF(liste!B37="","",liste!B37) | M37: =IF(liste!C37="","",liste!C37) | N37: =IF(liste!D37="","",liste!D37) -> BRITISH INDIAN OCEAN TERRITORY | O37: =IF(liste!E37="","",liste!E37) -> IO | P37: =IF(liste!F37="","",liste!F37) | Q37: =IF(liste!G37="","",liste!G37) | R37: =IF(liste!H37="","",liste!H37) | ... AF37: =IF(liste!V37="","",liste!V37)
K38: =IF(liste!A38="","",liste!A38) | L38: =IF(liste!B38="","",liste!B38) | M38: =IF(liste!C38="","",liste!C38) | N38: =IF(liste!D38="","",liste!D38) -> BRUNEI DARUSSALAM | O38: =IF(liste!E38="","",liste!E38) -> BN | P38: =IF(liste!F38="","",liste!F38) | Q38: =IF(liste!G38="","",liste!G38) | R38: =IF(liste!H38="","",liste!H38) | ... AF38: =IF(liste!V38="","",liste!V38)
K39: =IF(liste!A39="","",liste!A39) | L39: =IF(liste!B39="","",liste!B39) | M39: =IF(liste!C39="","",liste!C39) | N39: =IF(liste!D39="","",liste!D39) -> BULGARIA | O39: =IF(liste!E39="","",liste!E39) -> BG | P39: =IF(liste!F39="","",liste!F39) | Q39: =IF(liste!G39="","",liste!G39) | R39: =IF(liste!H39="","",liste!H39) | ... AF39: =IF(liste!V39="","",liste!V39)
K40: =IF(liste!A40="","",liste!A40) | L40: =IF(liste!B40="","",liste!B40) | M40: =IF(liste!C40="","",liste!C40) | N40: =IF(liste!D40="","",liste!D40) -> BURKINA FASO | O40: =IF(liste!E40="","",liste!E40) -> BF | P40: =IF(liste!F40="","",liste!F40) | Q40: =IF(liste!G40="","",liste!G40) | R40: =IF(liste!H40="","",liste!H40) | ... AF40: =IF(liste!V40="","",liste!V40)
...
